Workbook

Sheet 00_README
A1: HỆ THỐNG DỮ LIỆU MARKETING XUẤT KHẨU — DATA MODEL
A4: CÁCH DÙNG
A5: 1. Anh/chị CHỈ sửa các sheet bắt đầu bằng RAW_ (ô nền VÀNG, chữ XANH).
A6: 2. Các sheet BRG_ là bảng cầu nối quan hệ nhiều-nhiều (cũng sửa được).
A7: 3. Các sheet V_ (View) TỰ ĐỘNG tính từ RAW bằng công thức — KHÔNG sửa tay.
A8: 4. Thêm dòng mới: gõ tiếp ngay dưới bảng, Excel Table sẽ tự mở rộng.
A9: 5. Xong thì lưu; các View cập nhật tức thì (không cần Refresh).
A11: QUY ƯỚC MÀU
A12: Ô VÀNG + chữ XANH = dữ liệu anh/chị nhập/sửa (INPUT).
A13: Ô XANH NHẠT (View) = ô công thức tự tính (OUTPUT) — đừng gõ đè.
A14: Cột tiêu đề chữ VÀNG = cột KHÓA (ID) dùng để liên kết bảng — giữ giá trị duy nhất.
A16: SƠ ĐỒ QUAN HỆ (xem chi tiết ở sheet 90_Relationships)
... A25: — BỔ SUNG: Mô-đun Chiến lược Mô hình Xuất khẩu —
A26: RAW_Model | B26: 7 mô hình KD xuất khẩu + đặc tính.
A27: RAW_Market (mở rộng) | B27: Thêm cột G/H/I: PriorityRank, RecommendedModel, StrategyNote.
A28: RAW_BuyerCulture | B28: Văn hóa buyer theo quốc gia.
A29: RAW_Regulation | B29: Luật & quy định theo quốc gia (AutoFilter theo MarketID).
A30: RAW_Phase | B30: Lộ trình lai 4 giai đoạn.
A31: RAW_Action | B31: Việc 90 ngày.
A32: BRG_Market_Model | B32: Ma trận ưu tiên: điểm + thứ tự triển khai.
A33: V_PriorityMatrix | B33: MASTER — lưới Thị trường × Mô hình (tự cập nhật).
A34: V_MarketStrategy | B34: MASTER — tóm tắt chiến lược mỗi thị trường (tự cập nhật).

Sheet RAW_Company
A1: ① RAW_Company — Thông tin công ty (1 dòng/công ty)
A2: PK = CompanyID. Sửa trực tiếp các ô vàng.
A3: CompanyID | B3: CompanyName_VI | C3: CompanyName_EN | D3: FoundedYear | E3: Address_HQ | F3: Address_Factory | G3: RawMaterialZone | H3: Email | I3: Phone | J3: WeChat | K3: Zalo | L3: Website | M3: Vision | N3: Mission | O3: CoreValues | P3: CompetitiveEdge | Q3: ProductionCapacity | R3: Achievements
A4: C001 | B4: Công ty Cổ phần Nông Thủy Sản Mekong Delta Pride | C4: Mekong Delta Pride Agri-Aqua JSC | D4: 2015 | E4: Lô C12, KCN Trà Nóc 2, Q. Bình Thủy, TP. Cần Thơ | F4: KCN Sông Hậu, huyện Châu Thành, tỉnh Hậu Giang | G4: 320 ha sầu riêng liên kết (Tiền Giang, Đắk Lắk); 180 ha ao tôm/cá tra ASC (Sóc Trăng, Đồng Tháp) | H4: sales@mekongdeltapride.com | I4: +84 909 123 456 | J4: MekongPride_Export | K4: 0909123456 | L4: www.mekongdeltapride.com | M4: Trở thành nhà cung cấp nông–thủy sản Việt Nam đáng tin cậy nhất khu vực châu Á–Thái Bình Dương vào năm 2030. | N4: Mang nông sản và thủy sản Việt Nam đạt chuẩn quốc tế đến bàn ăn toàn cầu, cam kết truy xuất nguồn gốc 100% và chất lượng ổn định. | O4: Minh bạch – Chất lượng – Đúng hẹn – Bền vững – Đối tác dài hạn | P4: Vùng nguyên liệu khép kín farm-to-port; Kho lạnh 5.000 tấn + 4 hầm IQF -40°C; Lab kiểm kháng sinh tại chỗ; Đủ HACCP/ISO22000/ASC/GlobalGAP/BRC; 6 năm xuất khẩu ổn định | Q4: Sầu riêng 1.200 tấn/tháng; Tôm 800 tấn/tháng; Cá tra fillet 1.500 tấn/tháng; 3 dây chuyền IQF, 120 tấn/ngày | R4: Top 50 DN thủy sản VASEP 2023; Mã vùng trồng & cơ sở đóng gói GACC; Khách dài hạn EU & Quảng Châu; 6 năm 0 lô bị trả về

Sheet RAW_Product
A1: ② RAW_Product — Sản phẩm (nhiều dòng)
A2: PK = ProductID ; FK = CompanyID → RAW_Company.
A3: ProductID | B3: CompanyID | C3: Name_VI | D3: Name_EN | E3: HSCode | F3: Size | G3: Packing | H3: ShelfLife | I3: Temperature | J3: MOQ | K3: MonthlyCapacity | L3: USP
A4: P001 | B4: C001 | C4: Sầu riêng đông lạnh nguyên múi | D4: Frozen Durian (Ri6 & Monthong) | E4: 0811.90.00 | F4: Múi 100–150g; whole 1.8–3.5kg | G4: 1kg/túi × 10 túi/thùng | H4: 24 tháng | I4: -18°C | J4: 1×40ft (25 tấn) | K4: 1.200 tấn/tháng | L4: Cấp đông IQF giữ nguyên vị, tách múi thủ công, mã vùng trồng xuất TQ chính ngạch
A5: P002 | B5: C001 | C5: Tôm thẻ đông lạnh bóc vỏ | D5: Frozen Vannamei Shrimp (PD/PUD) | E5: 0306.17.00 | F5: 21/25, 26/30, 31/40, 41/50 (con/lb) | G5: 1kg block × 10/thùng; hoặc IQF 1kg/túi | H5: 24 tháng | I5: -18°C | J5: 1×40ft | K5: 800 tấn/tháng | L5: Nuôi ASC không kháng sinh, kiểm lab 100% lô, cấp đông trong 4h sau thu hoạch
A6: P003 | B6: C001 | C6: Cá tra fillet đông lạnh | D6: Frozen Pangasius Fillet | E6: 0304.62.00 | F6: 120-170, 170-220, 220-up (g) | G6: IQF 1kg × 10/thùng; mạ băng 10–20% | H6: 24 tháng | I6: -18°C | J6: 1×40ft | K6: 1.500 tấn/tháng | L6: Thịt trắng, mạ băng minh bạch đúng %, truy xuất từng ao nuôi qua QR

Sheet RAW_Certificate
A1: ③ RAW_Certificate — Chứng nhận (nhiều dòng)
A2: PK = CertID.
A3: CertID | B3: CertName | C3: IssuedBy | D3: Scope | E3: FileLink | F3: ExpiryDate
A4: CT001 | B4: HACCP | C4: NSF / Bureau Veritas | D4: Toàn nhà máy | E4: [dán link PDF] | F4: 2026-12-31
A5: CT002 | B5: ISO 22000:2018 | C5: Bureau Veritas | D5: Hệ thống ATTP | E5: [link] | F5: 2026-08-30
A6: CT003 | B6: ASC | C6: ASC / Control Union | D6: Vùng nuôi tôm & cá tra | E6: [link] | F6: 2027-03-15
A7: CT004 | B7: GlobalG.A.P | C7: Control Union | D7: Vùng trồng & nuôi | E7: [link] | F7: 2026-11-20
A8: CT005 | B8: BRC Food | C8: SGS | D8: Chế biến đông lạnh | E8: [link] | F8: 2026-10-05
A9: CT006 | B9: Mã vùng trồng & cơ sở đóng gói GACC | C9: Hải quan Trung Quốc (GACC) | D9: Xuất khẩu chính ngạch TQ | E9: [link] | F9: 2027-01-01
A10: CT007 | B10: BAP (Best Aquaculture Practices) | C10: GAA | D10: Trại nuôi & nhà máy | E10: [link] | F10: 2026-09-30
A11: CT008 | B11: HALAL | C11: HCA Vietnam | D11: Sản phẩm cá tra | E11: [link] | F11: 2026-12-01

Sheet RAW_Media
A1: ④ RAW_Media — Tư liệu hình ảnh/video (nhiều dòng)
A2: PK = MediaID.
A3: MediaID | B3: MediaType | C3: Title | D3: FileLink | E3: Note
A4: M001 | B4: Logo | C4: Logo vector chính | D4: [link] | E4: AI/PNG nền trong
A5: M002 | B5: Product Photo | C5: Bộ ảnh sầu riêng đông lạnh | D5: [link] | E5: 15–20 ảnh studio nền trắng
A6: M003 | B6: Product Photo | C6: Bộ ảnh tôm thẻ | D6: [link] | E6: Ảnh sản phẩm + đóng gói
A7: M004 | B7: Product Photo | C7: Bộ ảnh cá tra fillet | D7: [link] | E7: Ảnh sản phẩm + đóng gói
A8: M005 | B8: Video | C8: Video giới thiệu nhà máy 60–90s | D8: [link] | E8: YouTube/Drive
A9: M006 | B9: Facility Photo | C9: Ảnh vườn/ao & dây chuyền IQF | D9: [link] | E9: Vùng nguyên liệu + nhà máy

Sheet RAW_Market
A1: ⑤ RAW_Market — Thị trường (nhiều dòng)
A2: PK = MarketID. SharePercent lưu dạng phân số (0.45 = 45%).
A3: MarketID | B3: MarketName | C3: Country | D3: Language | E3: SharePercent | F3: Channel | G3: PriorityRank | H3: RecommendedModel_VI | I3: StrategyNote_VI
A4: MK001 | B4: Trung Quốc | C4: China | D4: 中文 | E4: 0.45 | F4: Nhập khẩu chính ngạch / Chợ đầu mối Quảng Châu | G4: 1 | H4: XK chính ngạch → NPP độc quyền → VPĐD Quảng Châu | I4: Thị trường lớn nhất. Bám chính ngạch, tránh tiểu ngạch. Cần người nói tiếng Trung + WeChat.
A5: MK002 | B5: Hà Lan (EU) | C5: Netherlands | D5: English | E5: 0.15 | F5: Chuỗi siêu thị / Nhà nhập khẩu | G5: 3 | H5: XK trực tiếp cho importer Rotterdam → Kho lạnh ký gửi làm hub EU | I5: Dùng Rotterdam làm hub trung chuyển toàn EU. Nhấn mạnh bền vững & truy xuất.
A6: MK003 | B6: Đức (EU) | C6: Germany | D6: English | E6: 0.10 | F6: Nhà nhập khẩu / Foodservice | G6: 4 | H6: XK trực tiếp cho importer/foodservice qua hub Hà Lan; không cần pháp nhân riêng | I6: Buyer kỹ tính, chuộng IFS/BRC. Phủ qua hub NL, không mở pháp nhân riêng.
A7: MK004 | B7: Mỹ | C7: USA | D7: English | E7: 0.15 | F7: Distributor / Retail | G7: 2 | H7: XK trực tiếp cho distributor + FSVP agent → Công ty con + kho lạnh khi đủ volume | I7: Kênh distributor gốc Á mạnh cho chả giò/cá tra. Cảnh giác SIMP & thuế AD/CVD với tôm.
A8: MK005 | B8: Hàn Quốc | C8: South Korea | D8: English | E8: 0.10 | F8: Importer / Retail | G8: 5 | H8: Nhà phân phối/importer bản địa (họ nắm giấy phép) → cân nhắc JV nếu mở rộng | I8: MFDS kiểm tra chặt. Tận dụng ưu đãi thuế VKFTA (C/O form VK).
A9: MK006 | B9: UAE (Trung Đông) | C9: UAE | D9: English | E9: 0.05 | F9: Importer / HORECA | G9: 6 | H9: XK trực tiếp cho importer Dubai (HALAL) → VPĐD/free-zone làm hub tái xuất GCC & châu Phi | I9: HALAL bắt buộc. Dubai là hub tái xuất GCC/châu Phi. Lưu ý Ramadan & cuối tuần T6-T7.

Sheet RAW_Config
A1: ⑥ RAW_Config — Tham số hệ thống (key–value)
A2: PK = ConfigKey.
A3: ConfigKey | B3: ConfigValue | C3: Note
A4: ActiveCompanyID | B4: C001 | C4: Công ty đang chọn để xuất tài liệu
A5: PriorityMarket | B5: Trung Quốc (chính ngạch) + EU + Trung Đông
A6: PrimaryLanguage | B6: English
A7: SecondaryLanguage | B7: 中文 (Chinese)
A8: BrandVoice | B8: Chuyên nghiệp, đáng tin cậy, nhấn mạnh minh bạch & truy xuất nguồn gốc; giọng đối tác B2B dài hạn
A9: DriveLink | B9: [dán link Google Drive tổng]
A10: Calendly | B10: [dán link Calendly]

Sheet BRG_Product_Certificate
A1: BRG_Product_Certificate — Sản phẩm ↔ Chứng nhận (N:N)
A3: LinkID | B3: ProductID | C3: CertID
A4: PC01 | B4: P001 | C4: CT001
A5: PC02 | B5: P001 | C5: CT002
A6: PC03 | B6: P001 | C6: CT006
A7: PC04 | B7: P001 | C7: CT004
A8: PC05 | B8: P002 | C8: CT003
A9: PC06 | B9: P002 | C9: CT007
A10: PC07 | B10: P002 | C10: CT001
A11: PC08 | B11: P002 | C11: CT005
A12: PC09 | B12: P003 | C12: CT003
A13: PC10 | B13: P003 | C13: CT004
A14: PC11 | B14: P003 | C14: CT002
... A16: PC13 | B16: P003 | C16: CT008

Sheet BRG_Product_Media
A1: BRG_Product_Media — Sản phẩm ↔ Media (N:N)
A3: LinkID | B3: ProductID | C3: MediaID
A4: PM01 | B4: P001 | C4: M002
A5: PM02 | B5: P002 | C5: M003
A6: PM03 | B6: P003 | C6: M004

Sheet BRG_Company_Certificate
A1: BRG_Company_Certificate — Công ty ↔ Chứng nhận (N:N)
A3: LinkID | B3: CompanyID | C3: CertID
A4: CC01 | B4: C001 | C4: CT001
A5: CC02 | B5: C001 | C5: CT002
A6: CC03 | B6: C001 | C6: CT003
A7: CC04 | B7: C001 | C7: CT004
A8: CC05 | B8: C001 | C8: CT005
A9: CC06 | B9: C001 | C9: CT006
A10: CC07 | B10: C001 | C10: CT007
A11: CC08 | B11: C001 | C11: CT008

Sheet BRG_Company_Market
A1: BRG_Company_Market — Công ty ↔ Thị trường (N:N)
A3: LinkID | B3: CompanyID | C3: MarketID
A4: CM01 | B4: C001 | C4: MK001
A5: CM02 | B5: C001 | C5: MK002
A6: CM03 | B6: C001 | C6: MK003
A7: CM04 | B7: C001 | C7: MK004
A8: CM05 | B8: C001 | C8: MK005
A9: CM06 | B9: C001 | C9: MK006

Sheet V_CompanyProfile
A1: V_CompanyProfile — TỰ ĐỘNG từ RAW (chọn công ty ở RAW_Config!ActiveCompanyID)
A3: Trường | B3: Giá trị (tự động)
A4: Company ID | B4: =INDEX('RAW_Company'!$A:$A,MATCH(INDEX('RAW_Config'!$B:$B,MATCH("ActiveCompanyID",'RAW_Config'!$A:$A,0)),'RAW_Company'!$A:$A,0)) -> C001
A5: Tên công ty (VI) | B5: =INDEX('RAW_Company'!$B:$B,MATCH(INDEX('RAW_Config'!$B:$B,MATCH("ActiveCompanyID",'RAW_Config'!$A:$A,0)),'RAW_Company'!$A:$A,0)) -> Công ty Cổ phần Nông Thủy Sản Mekong Delta Pride
A6: Company Name (EN) | B6: =INDEX('RAW_Company'!$C:$C,MATCH(INDEX('RAW_Config'!$B:$B,MATCH("ActiveCompanyID",'RAW_Config'!$A:$A,0)),'RAW_Company'!$A:$A,0)) -> Mekong Delta Pride Agri-Aqua JSC
A7: Năm thành lập | B7: =INDEX('RAW_Company'!$D:$D,MATCH(INDEX('RAW_Config'!$B:$B,MATCH("ActiveCompanyID",'RAW_Config'!$A:$A,0)),'RAW_Company'!$A:$A,0)) -> 2015
A8: Trụ sở | B8: =INDEX('RAW_Company'!$E:$E,MATCH(INDEX('RAW_Config'!$B:$B,MATCH("ActiveCompanyID",'RAW_Config'!$A:$A,0)),'RAW_Company'!$A:$A,0)) -> Lô C12, KCN Trà Nóc 2, Q. Bình Thủy, TP. Cần Thơ
A9: Nhà máy | B9: =INDEX('RAW_Company'!$F:$F,MATCH(INDEX('RAW_Config'!$B:$B,MATCH("ActiveCompanyID",'RAW_Config'!$A:$A,0)),'RAW_Company'!$A:$A,0)) -> KCN Sông Hậu, huyện Châu Thành, tỉnh Hậu Giang
A10: Vùng nguyên liệu | B10: =INDEX('RAW_Company'!$G:$G,MATCH(INDEX('RAW_Config'!$B:$B,MATCH("ActiveCompanyID",'RAW_Config'!$A:$A,0)),'RAW_Company'!$A:$A,0)) -> 320 ha sầu riêng liên kết (Tiền Giang, Đắk Lắk); 180 ha ao tôm/cá tra ASC (Sóc Trăng, Đồng Tháp)
A11: Email | B11: =INDEX('RAW_Company'!$H:$H,MATCH(INDEX('RAW_Config'!$B:$B,MATCH("ActiveCompanyID",'RAW_Config'!$A:$A,0)),'RAW_Company'!$A:$A,0)) -> sales@mekongdeltapride.com
A12: Phone | B12: =INDEX('RAW_Company'!$I:$I,MATCH(INDEX('RAW_Config'!$B:$B,MATCH("ActiveCompanyID",'RAW_Config'!$A:$A,0)),'RAW_Company'!$A:$A,0)) -> +84 909 123 456
A13: WeChat | B13: =INDEX('RAW_Company'!$J:$J,MATCH(INDEX('RAW_Config'!$B:$B,MATCH("ActiveCompanyID",'RAW_Config'!$A:$A,0)),'RAW_Company'!$A:$A,0)) -> MekongPride_Export
A14: Zalo | B14: =INDEX('RAW_Company'!$K:$K,MATCH(INDEX('RAW_Config'!$B:$B,MATCH("ActiveCompanyID",'RAW_Config'!$A:$A,0)),'RAW_Company'!$A:$A,0)) -> 0909123456
A15: Website | B15: =INDEX('RAW_Company'!$L:$L,MATCH(INDEX('RAW_Config'!$B:$B,MATCH("ActiveCompanyID",'RAW_Config'!$A:$A,0)),'RAW_Company'!$A:$A,0)) -> www.mekongdeltapride.com
A16: Vision | B16: =INDEX('RAW_Company'!$M:$M,MATCH(INDEX('RAW_Config'!$B:$B,MATCH("ActiveCompanyID",'RAW_Config'!$A:$A,0)),'RAW_Company'!$A:$A,0)) -> Trở thành nhà cung cấp nông–thủy sản Việt Nam đáng tin cậy nhất khu vực châu Á–Thái Bình Dương vào năm 2030.
A17: Mission | B17: =INDEX('RAW_Company'!$N:$N,MATCH(INDEX('RAW_Config'!$B:$B,MATCH("ActiveCompanyID",'RAW_Config'!$A:$A,0)),'RAW_Company'!$A:$A,0)) -> Mang nông sản và thủy sản Việt Nam đạt chuẩn quốc tế đến bàn ăn toàn cầu, cam kết truy xuất nguồn gốc 100% và chất lượng ổn định.
A18: Core Values | B18: =INDEX('RAW_Company'!$O:$O,MATCH(INDEX('RAW_Config'!$B:$B,MATCH("ActiveCompanyID",'RAW_Config'!$A:$A,0)),'RAW_Company'!$A:$A,0)) -> Minh bạch – Chất lượng – Đúng hẹn – Bền vững – Đối tác dài hạn
A19: Competitive Edge | B19: =INDEX('RAW_Company'!$P:$P,MATCH(INDEX('RAW_Config'!$B:$B,MATCH("ActiveCompanyID",'RAW_Config'!$A:$A,0)),'RAW_Company'!$A:$A,0)) -> Vùng nguyên liệu khép kín farm-to-port; Kho lạnh 5.000 tấn + 4 hầm IQF -40°C; Lab kiểm kháng sinh tại chỗ; Đủ HACCP/ISO22000/ASC/GlobalGAP/BRC; 6 năm xuất khẩu ổn định
A20: Production Capacity | B20: =INDEX('RAW_Company'!$Q:$Q,MATCH(INDEX('RAW_Config'!$B:$B,MATCH("ActiveCompanyID",'RAW_Config'!$A:$A,0)),'RAW_Company'!$A:$A,0)) -> Sầu riêng 1.200 tấn/tháng; Tôm 800 tấn/tháng; Cá tra fillet 1.500 tấn/tháng; 3 dây chuyền IQF, 120 tấn/ngày
A21: Achievements | B21: =INDEX('RAW_Company'!$R:$R,MATCH(INDEX('RAW_Config'!$B:$B,MATCH("ActiveCompanyID",'RAW_Config'!$A:$A,0)),'RAW_Company'!$A:$A,0)) -> Top 50 DN thủy sản VASEP 2023; Mã vùng trồng & cơ sở đóng gói GACC; Khách dài hạn EU & Quảng Châu; 6 năm 0 lô bị trả về
A22: Số thị trường | B22: =COUNTIFS(BRG_Company_Market!$B:$B,INDEX('RAW_Config'!$B:$B,MATCH("ActiveCompanyID",'RAW_Config'!$A:$A,0))) -> 6
A23: Số chứng nhận (công ty) | B23: =COUNTIFS(BRG_Company_Certificate!$B:$B,INDEX('RAW_Config'!$B:$B,MATCH("ActiveCompanyID",'RAW_Config'!$A:$A,0))) -> 8

Sheet V_Catalogue
A1: V_Catalogue — TỰ ĐỘNG: mỗi dòng 1 sản phẩm (thêm SP ở RAW_Product là tự có)
A3: ProductID | B3: Product (EN) | C3: Product (VI) | D3: HS Code | E3: MOQ | F3: Monthly Capacity | G3: # Certs | H3: # Media | I3: Company (EN)
A4: ='RAW_Product'!A4 -> P001 | B4: ='RAW_Product'!D4 -> Frozen Durian (Ri6 & Monthong) | C4: ='RAW_Product'!C4 -> Sầu riêng đông lạnh nguyên múi | D4: ='RAW_Product'!E4 -> 0811.90.00 | E4: ='RAW_Product'!J4 -> 1×40ft (25 tấn) | F4: ='RAW_Product'!K4 -> 1.200 tấn/tháng | G4: =COUNTIFS(BRG_Product_Certificate!$B:$B,$A4) -> 4 | H4: =COUNTIFS(BRG_Product_Media!$B:$B,$A4) -> 1 | I4: =INDEX('RAW_Company'!$C:$C,MATCH('RAW_Product'!B4,'RAW_Company'!$A:$A,0)) -> Mekong Delta Pride Agri-Aqua JSC
A5: ='RAW_Product'!A5 -> P002 | B5: ='RAW_Product'!D5 -> Frozen Vannamei Shrimp (PD/PUD) | C5: ='RAW_Product'!C5 -> Tôm thẻ đông lạnh bóc vỏ | D5: ='RAW_Product'!E5 -> 0306.17.00 | E5: ='RAW_Product'!J5 -> 1×40ft | F5: ='RAW_Product'!K5 -> 800 tấn/tháng | G5: =COUNTIFS(BRG_Product_Certificate!$B:$B,$A5) -> 4 | H5: =COUNTIFS(BRG_Product_Media!$B:$B,$A5) -> 1 | I5: =INDEX('RAW_Company'!$C:$C,MATCH('RAW_Product'!B5,'RAW_Company'!$A:$A,0)) -> Mekong Delta Pride Agri-Aqua JSC
A6: ='RAW_Product'!A6 -> P003 | B6: ='RAW_Product'!D6 -> Frozen Pangasius Fillet | C6: ='RAW_Product'!C6 -> Cá tra fillet đông lạnh | D6: ='RAW_Product'!E6 -> 0304.62.00 | E6: ='RAW_Product'!J6 -> 1×40ft | F6: ='RAW_Product'!K6 -> 1.500 tấn/tháng | G6: =COUNTIFS(BRG_Product_Certificate!$B:$B,$A6) -> 5 | H6: =COUNTIFS(BRG_Product_Media!$B:$B,$A6) -> 1 | I6: =INDEX('RAW_Company'!$C:$C,MATCH('RAW_Product'!B6,'RAW_Company'!$A:$A,0)) -> Mekong Delta Pride Agri-Aqua JSC

Sheet V_OnePager
A1: V_OnePager — Gõ ProductID vào ô B3, mọi thông tin tự điền
A3: Chọn ProductID → | B3: P001
A5: Trường | B5: Giá trị (tự động)
A6: Product (EN) | B6: =INDEX('RAW_Product'!$D:$D,MATCH($B$3,'RAW_Product'!$A:$A,0)) -> Frozen Durian (Ri6 & Monthong)
A7: Sản phẩm (VI) | B7: =INDEX('RAW_Product'!$C:$C,MATCH($B$3,'RAW_Product'!$A:$A,0)) -> Sầu riêng đông lạnh nguyên múi
A8: HS Code | B8: =INDEX('RAW_Product'!$E:$E,MATCH($B$3,'RAW_Product'!$A:$A,0)) -> 0811.90.00
A9: Size | B9: =INDEX('RAW_Product'!$F:$F,MATCH($B$3,'RAW_Product'!$A:$A,0)) -> Múi 100–150g; whole 1.8–3.5kg
A10: Packing | B10: =INDEX('RAW_Product'!$G:$G,MATCH($B$3,'RAW_Product'!$A:$A,0)) -> 1kg/túi × 10 túi/thùng
A11: Shelf life | B11: =INDEX('RAW_Product'!$H:$H,MATCH($B$3,'RAW_Product'!$A:$A,0)) -> 24 tháng
A12: Temperature | B12: =INDEX('RAW_Product'!$I:$I,MATCH($B$3,'RAW_Product'!$A:$A,0)) -> -18°C
A13: MOQ | B13: =INDEX('RAW_Product'!$J:$J,MATCH($B$3,'RAW_Product'!$A:$A,0)) -> 1×40ft (25 tấn)
A14: Monthly Capacity | B14: =INDEX('RAW_Product'!$K:$K,MATCH($B$3,'RAW_Product'!$A:$A,0)) -> 1.200 tấn/tháng
A15: USP | B15: =INDEX('RAW_Product'!$L:$L,MATCH($B$3,'RAW_Product'!$A:$A,0)) -> Cấp đông IQF giữ nguyên vị, tách múi thủ công, mã vùng trồng xuất TQ chính ngạch
A17: CHỨNG NHẬN CỦA SẢN PHẨM
A18: CertID | B18: Có? (X)
A19: ='RAW_Certificate'!A4 -> CT001 | B19: =IF(COUNTIFS(BRG_Product_Certificate!$B:$B,$B$3,BRG_Product_Certificate!$C:$C,'RAW_Certificate'!A4)>0,"X","") -> X
A20: ='RAW_Certificate'!A5 -> CT002 | B20: =IF(COUNTIFS(BRG_Product_Certificate!$B:$B,$B$3,BRG_Product_Certificate!$C:$C,'RAW_Certificate'!A5)>0,"X","") -> X
A21: ='RAW_Certificate'!A6 -> CT003 | B21: =IF(COUNTIFS(BRG_Product_Certificate!$B:$B,$B$3,BRG_Product_Certificate!$C:$C,'RAW_Certificate'!A6)>0,"X","")
A22: ='RAW_Certificate'!A7 -> CT004 | B22: =IF(COUNTIFS(BRG_Product_Certificate!$B:$B,$B$3,BRG_Product_Certificate!$C:$C,'RAW_Certificate'!A7)>0,"X","") -> X
A23: ='RAW_Certificate'!A8 -> CT005 | B23: =IF(COUNTIFS(BRG_Product_Certificate!$B:$B,$B$3,BRG_Product_Certificate!$C:$C,'RAW_Certificate'!A8)>0,"X","")
A24: ='RAW_Certificate'!A9 -> CT006 | B24: =IF(COUNTIFS(BRG_Product_Certificate!$B:$B,$B$3,BRG_Product_Certificate!$C:$C,'RAW_Certificate'!A9)>0,"X","") -> X
A25: ='RAW_Certificate'!A10 -> CT007 | B25: =IF(COUNTIFS(BRG_Product_Certificate!$B:$B,$B$3,BRG_Product_Certificate!$C:$C,'RAW_Certificate'!A10)>0,"X","")
A26: ='RAW_Certificate'!A11 -> CT008 | B26: =IF(COUNTIFS(BRG_Product_Certificate!$B:$B,$B$3,BRG_Product_Certificate!$C:$C,'RAW_Certificate'!A11)>0,"X","")

Sheet V_ProductCertMatrix
A1: V_ProductCertMatrix — Ma trận Sản phẩm × Chứng nhận (X = có)
A3: Product \ Cert | B3: HACCP | C3: ISO 22000:2018 | D3: ASC | E3: GlobalG.A.P | F3: BRC Food | G3: Mã vùng trồng & cơ sở đóng gói GACC | H3: BAP (Best Aquaculture Practices) | I3: HALAL
A4: ='RAW_Product'!D4 -> Frozen Durian (Ri6 & Monthong) | B4: =IF(COUNTIFS(BRG_Product_Certificate!$B:$B,'RAW_Product'!$A4,BRG_Product_Certificate!$C:$C,'RAW_Certificate'!$A$4)>0,"X","") -> X | C4: =IF(COUNTIFS(BRG_Product_Certificate!$B:$B,'RAW_Product'!$A4,BRG_Product_Certificate!$C:$C,'RAW_Certificate'!$A$5)>0,"X","") -> X | D4: =IF(COUNTIFS(BRG_Product_Certificate!$B:$B,'RAW_Product'!$A4,BRG_Product_Certificate!$C:$C,'RAW_Certificate'!$A$6)>0,"X","") | E4: =IF(COUNTIFS(BRG_Product_Certificate!$B:$B,'RAW_Product'!$A4,BRG_Product_Certificate!$C:$C,'RAW_Certificate'!$A$7)>0,"X","") -> X | F4: =IF(COUNTIFS(BRG_Product_Certificate!$B:$B,'RAW_Product'!$A4,BRG_Product_Certificate!$C:$C,'RAW_Certificate'!$A$8)>0,"X","") | G4: =IF(COUNTIFS(BRG_Product_Certificate!$B:$B,'RAW_Product'!$A4,BRG_Product_Certificate!$C:$C,'RAW_Certificate'!$A$9)>0,"X","") -> X | H4: =IF(COUNTIFS(BRG_Product_Certificate!$B:$B,'RAW_Product'!$A4,BRG_Product_Certificate!$C:$C,'RAW_Certificate'!$A$10)>0,"X","") | I4: =IF(COUNTIFS(BRG_Product_Certificate!$B:$B,'RAW_Product'!$A4,BRG_Product_Certificate!$C:$C,'RAW_Certificate'!$A$11)>0,"X","")
A5: ='RAW_Product'!D5 -> Frozen Vannamei Shrimp (PD/PUD) | B5: =IF(COUNTIFS(BRG_Product_Certificate!$B:$B,'RAW_Product'!$A5,BRG_Product_Certificate!$C:$C,'RAW_Certificate'!$A$4)>0,"X","") -> X | C5: =IF(COUNTIFS(BRG_Product_Certificate!$B:$B,'RAW_Product'!$A5,BRG_Product_Certificate!$C:$C,'RAW_Certificate'!$A$5)>0,"X","") | D5: =IF(COUNTIFS(BRG_Product_Certificate!$B:$B,'RAW_Product'!$A5,BRG_Product_Certificate!$C:$C,'RAW_Certificate'!$A$6)>0,"X","") -> X | E5: =IF(COUNTIFS(BRG_Product_Certificate!$B:$B,'RAW_Product'!$A5,BRG_Product_Certificate!$C:$C,'RAW_Certificate'!$A$7)>0,"X","") | F5: =IF(COUNTIFS(BRG_Product_Certificate!$B:$B,'RAW_Product'!$A5,BRG_Product_Certificate!$C:$C,'RAW_Certificate'!$A$8)>0,"X","") -> X | G5: =IF(COUNTIFS(BRG_Product_Certificate!$B:$B,'RAW_Product'!$A5,BRG_Product_Certificate!$C:$C,'RAW_Certificate'!$A$9)>0,"X","") | H5: =IF(COUNTIFS(BRG_Product_Certificate!$B:$B,'RAW_Product'!$A5,BRG_Product_Certificate!$C:$C,'RAW_Certificate'!$A$10)>0,"X","") -> X | I5: =IF(COUNTIFS(BRG_Product_Certificate!$B:$B,'RAW_Product'!$A5,BRG_Product_Certificate!$C:$C,'RAW_Certificate'!$A$11)>0,"X","")
A6: ='RAW_Product'!D6 -> Frozen Pangasius Fillet | B6: =IF(COUNTIFS(BRG_Product_Certificate!$B:$B,'RAW_Product'!$A6,BRG_Product_Certificate!$C:$C,'RAW_Certificate'!$A$4)>0,"X","") | C6: =IF(COUNTIFS(BRG_Product_Certificate!$B:$B,'RAW_Product'!$A6,BRG_Product_Certificate!$C:$C,'RAW_Certificate'!$A$5)>0,"X","") -> X | D6: =IF(COUNTIFS(BRG_Product_Certificate!$B:$B,'RAW_Product'!$A6,BRG_Product_Certificate!$C:$C,'RAW_Certificate'!$A$6)>0,"X","") -> X | E6: =IF(COUNTIFS(BRG_Product_Certificate!$B:$B,'RAW_Product'!$A6,BRG_Product_Certificate!$C:$C,'RAW_Certificate'!$A$7)>0,"X","") -> X | F6: =IF(COUNTIFS(BRG_Product_Certificate!$B:$B,'RAW_Product'!$A6,BRG_Product_Certificate!$C:$C,'RAW_Certificate'!$A$8)>0,"X","") -> X | G6: =IF(COUNTIFS(BRG_Product_Certificate!$B:$B,'RAW_Product'!$A6,BRG_Product_Certificate!$C:$C,'RAW_Certificate'!$A$9)>0,"X","") | H6: =IF(COUNTIFS(BRG_Product_Certificate!$B:$B,'RAW_Product'!$A6,BRG_Product_Certificate!$C:$C,'RAW_Certificate'!$A$10)>0,"X","") | I6: =IF(COUNTIFS(BRG_Product_Certificate!$B:$B,'RAW_Product'!$A6,BRG_Product_Certificate!$C:$C,'RAW_Certificate'!$A$11)>0,"X","") -> X

Sheet 90_Relationships
A1: 90_Relationships — Bản đồ khóa PK/FK (dùng khi import vào Power BI)
A3: From Table | B3: From Column (FK) | C3: To Table | D3: To Column (PK) | E3: Cardinality
A4: RAW_Product | B4: CompanyID | C4: RAW_Company | D4: CompanyID | E4: Many-to-One
A5: BRG_Product_Certificate | B5: ProductID | C5: RAW_Product | D5: ProductID | E5: Many-to-One
A6: BRG_Product_Certificate | B6: CertID | C6: RAW_Certificate | D6: CertID | E6: Many-to-One
A7: BRG_Product_Media | B7: ProductID | C7: RAW_Product | D7: ProductID | E7: Many-to-One
A8: BRG_Product_Media | B8: MediaID | C8: RAW_Media | D8: MediaID | E8: Many-to-One
A9: BRG_Company_Certificate | B9: CompanyID | C9: RAW_Company | D9: CompanyID | E9: Many-to-One
A10: BRG_Company_Certificate | B10: CertID | C10: RAW_Certificate | D10: CertID | E10: Many-to-One
A11: BRG_Company_Market | B11: CompanyID | C11: RAW_Company | D11: CompanyID | E11: Many-to-One
A12: BRG_Company_Market | B12: MarketID | C12: RAW_Market | D12: MarketID | E12: Many-to-One
A14: Ghi chú: Import 6 bảng RAW + 4 bảng BRG vào Power BI (Get Data → Excel). Trong Model view, tạo relationship theo đúng bảng trên. Đặt các bảng RAW_ làm dimension, BRG_ làm bảng cầu nối, hướng lọc Single. RAW_Config để riêng (không nối).

Sheet RAW_Model
A1: RAW_Model — 7 mô hình kinh doanh xuất khẩu
A2: PK = ModelID. Xếp theo mức dấn thân tăng dần. Sửa trực tiếp trong bảng.
A3: ModelID | B3: ModelName_VI | C3: ModelName_EN | D3: HowItWorks_VI | E3: CapitalRisk | F3: MarketControl | G3: Margin | H3: BestWhen_VI
A4: MOD1 | B4: XK trực tiếp cho nhà nhập khẩu | C4: Direct export (FOB/CIF) to importer | D4: Bán thẳng cho importer/distributor nước ngoài theo FOB/CFR/CIF; họ lo thông quan & phân phối. | E4: Thấp | F4: Thấp | G4: Trung bình | H4: Khởi đầu mọi thị trường; hàng số lượng lớn, tiêu chuẩn hóa.
A5: MOD2 | B5: XK gián tiếp qua trading/broker | C5: Indirect export via trading/broker | D5: Bán qua công ty thương mại/broker; họ tìm đầu ra, ta ít tiếp xúc khách cuối. | E5: Rất thấp | F5: Rất thấp | G5: Thấp | H5: Xả hàng, thị trường xa/khó, thiếu nguồn lực bán hàng.
A6: MOD3 | B6: Nhà phân phối/đại lý độc quyền | C6: Exclusive distributor / agent | D6: Chỉ định một đối tác bản địa độc quyền theo vùng, cam kết doanh số & marketing chung. | E6: TB-thấp | F6: Trung bình | G6: TB-cao | H6: Cần phủ kênh nhanh, xây thương hiệu khi chưa lập pháp nhân.
A7: MOD4 | B7: Văn phòng đại diện (VPĐD) | C7: Representative office | D7: Hiện diện pháp lý để xúc tiến, chăm khách, QC — KHÔNG được xuất hóa đơn bán. | E7: Trung bình | F7: TB-cao | G7: Trung bình | H7: Thị trường chiến lược cần cắm cờ, gần buyer lớn, hỗ trợ NPP.
A8: MOD5 | B8: Công ty con + kho lạnh | C8: Subsidiary + cold warehouse (importer of record) | D8: Lập công ty tại nước NK, tự nhập khẩu, trữ kho lạnh, bán cho retail/foodservice. | E8: Cao | F8: Rất cao | G8: Cao nhất | H8: Volume đủ lớn & ổn định; muốn nắm khách cuối, giá & thương hiệu.
A9: MOD6 | B9: Liên doanh | C9: Joint venture (JV) | D9: Góp vốn với đối tác bản địa (phân phối/chế biến), chia sẻ mạng lưới & rủi ro. | E9: Cao (chia sẻ) | F9: Cao | G9: Cao | H9: Thị trường rào cản cao (giấy phép, quan hệ), cần nội địa hóa.
A10: MOD7 | B10: Kho ngoại quan + TMĐT B2B/B2C | C10: Bonded/consignment hub + e-commerce | D10: Ký gửi hàng tại kho hub gần khách; bán qua nền tảng (Amazon, Tmall Global, sàn B2B). | E10: Trung bình | F10: TB-cao | G10: Cao | H10: Sản phẩm đóng gói bán lẻ (chả giò); muốn test thị trường nhanh.

Sheet RAW_BuyerCulture
A1: RAW_BuyerCulture — Văn hóa làm việc của buyer theo quốc gia
A2: FK = MarketID → RAW_Market. Một dòng / thị trường. Sửa trực tiếp.
A3: MarketID | B3: Country | C3: DecisionStyle_VI | D3: Communication_VI | E3: KeyValues_VI | F3: PracticalTips_VI
A4: MK001 | B4: China | C4: Dựa quan hệ (关系 guanxi) & tin cậy cá nhân; gặp mặt, ăn uống trước khi chốt. | D4: WeChat là chuẩn; cần người nói tiếng Trung; phản hồi nhanh. | E4: Tốc độ giao & ổn định nguồn; giá cạnh tranh. | F4: Đàm phán giá gắt, đơn lớn nhưng ép công nợ — kiểm soát rủi ro thanh toán (L/C, cọc).
A5: MK002 | B5: Netherlands | C5: Thẳng thắn, dựa số liệu, quyết nhanh khi đủ dữ kiện. | D5: Email/họp đúng giờ, súc tích; ghét vòng vo. | E5: Bền vững & chứng nhận (ASC, MSC, GlobalG.A.P), truy xuất minh bạch. | F5: Chuẩn bị hồ sơ chứng nhận đầy đủ; leverage vị trí cảng Rotterdam.
A6: MK003 | B6: Germany | C6: Kỹ tính, chuộng quy trình & giấy tờ; kiểm tra kỹ trước cam kết dài hạn. | D6: Trang trọng, chi tiết, đúng hẹn; ưu tiên văn bản. | E6: Chất lượng ổn định tuyệt đối; BRC/IFS, organic; trách nhiệm chuỗi cung ứng. | F6: Sai lệch chất lượng bị phạt nặng — kiểm soát QC. Trung thành khi đã tin tưởng.
A7: MK004 | B7: USA | C7: Thực dụng, dựa hiệu suất & hợp đồng chặt; quyết nhanh. | D7: Trực tiếp, ngắn gọn, tập trung ROI & điều khoản. | E7: Giá cạnh tranh, nguồn cung lớn ổn định, trách nhiệm pháp lý & bảo hiểm. | F7: Chuẩn bị hợp đồng, bảo hiểm trách nhiệm, truy xuất. Khai thác kênh ethnic gốc Á.
A8: MK005 | B8: South Korea | C8: Tôn ti, quyết định tập thể; cần nhiều vòng gặp & kiên nhẫn. | D8: Lịch sự, trang trọng; xây quan hệ trước khi bàn giá. | E8: Chất lượng & đóng gói cực cao; ngoại hình sản phẩm; test mẫu kỹ. | F8: Đầu tư mẫu & bao bì. Dùng ưu đãi thuế VKFTA làm lợi thế cạnh tranh.
A9: MK006 | B9: UAE | C9: Dựa quan hệ & uy tín cá nhân; đàm phán linh hoạt, không gấp gáp. | D9: Tôn trọng lễ nghi; gặp mặt quan trọng; kiên nhẫn. | E9: Đối tác dài hạn, đáng tin; sản phẩm HALAL đúng chuẩn. | F9: Lưu ý Ramadan & cuối tuần T6-T7. Dùng Dubai làm bàn đạp tái xuất.

Sheet RAW_Regulation
A1: RAW_Regulation — Luật & quy định theo quốc gia
A2: PK = RegID ; FK = MarketID. Dùng AutoFilter/lọc theo MarketID. Sửa trực tiếp.
A3: RegID | B3: MarketID | C3: Country | D3: RegName | E3: Authority | F3: Requirement_VI | G3: Mandatory
A4: REG001 | B4: MK001 | C4: China | D4: Đăng ký GACC (Lệnh 248/249) | E4: Hải quan TQ (GACC) | F4: Đăng ký nhà máy & mã vùng trồng; sầu riêng phải nằm trong Nghị định thư. | G4: Bắt buộc
A5: REG002 | B5: MK001 | C5: China | D5: Kiểm dịch CIQ & ghi nhãn | E5: CIQ / GACC | F5: Kiểm dịch động thực vật, dán nhãn tiếng Trung, truy xuất nguồn gốc. | G5: Bắt buộc
A6: REG003 | B6: MK001 | C6: China | D6: Xuất khẩu chính ngạch | E6: Hải quan TQ | F6: Đi chính ngạch có hợp đồng, hóa đơn; tránh tiểu ngạch rủi ro cao. | G6: Khuyến nghị
A7: REG004 | B7: MK002 | C7: Netherlands | D7: EU Health Certificate + Approved Establishment | E7: EU / NVWA | F7: Cơ sở nằm trong danh sách nhà máy được EU phê duyệt; chứng thư thú y/vệ sinh. | G7: Bắt buộc
A8: REG005 | B8: MK002 | C8: Netherlands | D8: Chứng nhận khai thác IUU | E8: EU | F8: Thủy sản khai thác cần chứng nhận IUU; giới hạn dư lượng & kháng sinh chặt. | G8: Bắt buộc
A9: REG006 | B9: MK002 | C9: Netherlands | D9: Kiểm soát tại BIP & EUDR | E9: EU / BIP | F9: Kiểm tra tại trạm cửa khẩu (BIP); EUDR nếu liên quan phá rừng. | G9: Bắt buộc
A10: REG007 | B10: MK003 | C10: Germany | D10: Khung EU (Health Cert, IUU, dư lượng) | E10: EU / BVL | F10: Áp dụng toàn bộ quy định EU về ATTP thủy sản. | G10: Bắt buộc
A11: REG008 | B11: MK003 | C11: Germany | D11: Luật chuỗi cung ứng (LkSG) | E11: CHLB Đức | F11: Nghĩa vụ thẩm định nhân quyền & môi trường trong chuỗi cung ứng. | G11: Bắt buộc
A12: REG009 | B12: MK003 | C12: Germany | D12: Tiêu chuẩn IFS Food & ghi nhãn Đức | E12: Retail Đức | F12: IFS Food gần như bắt buộc với retail; nhãn tiếng Đức, thông tin dị ứng nguyên. | G12: Bắt buộc (retail)
A13: REG010 | B13: MK004 | C13: USA | D13: Đăng ký cơ sở FDA + FSMA/FSVP | E13: US FDA | F13: Đăng ký cơ sở; tuân thủ FSMA/FSVP (cần US agent); HACCP thủy sản. | G13: Bắt buộc
A14: REG011 | B14: MK004 | C14: USA | D14: SIMP (giám sát NK thủy sản) | E14: NOAA/US | F14: Chương trình giám sát nhập khẩu với tôm & một số loài; truy xuất từ khai thác/nuôi. | G14: Bắt buộc (tôm)
... A22: REG019 | B22: MK006 | C22: UAE | D22: Free-zone (JAFZA) sở hữu 100% | E22: JAFZA | F22: Cho phép 100% sở hữu nước ngoài — thuận cho VPĐD/kho hub. | G22: Tùy chọn

Sheet RAW_Phase
A1: RAW_Phase — Lộ trình triển khai (chiến lược lai 4 giai đoạn)
A2: PK = PhaseID. Chuyển giai đoạn khi volume & biên LN đủ gánh chi phí cố định. Sửa trực tiếp.
A3: PhaseID | B3: PhaseName_VI | C3: Timeline | D3: Objective_VI | E3: KeyActivities_VI | F3: ModelApplied_VI
A4: PH1 | B4: Thâm nhập | C4: 0–12 tháng | D4: Nhẹ vốn, tạo dòng tiền, học thị trường | E4: XK trực tiếp FOB/CIF cho importer đã sàng lọc; dự hội chợ (SIAL, Gulfood, Seafood Expo, CIIE); chuẩn hóa hồ sơ HACCP/BRC/GACC/HALAL/FSVP. | F4: XK trực tiếp + gián tiếp
A5: PH2 | B5: Phủ kênh | C5: 12–24 tháng | D5: Xây quan hệ độc quyền, tăng độ phủ | E5: Chỉ định nhà phân phối độc quyền theo vùng; KPI doanh số + đồng đầu tư marketing; đặt tồn kho lạnh ký gửi gần cụm khách. | F5: Nhà phân phối độc quyền + consignment
A6: PH3 | B6: Cắm cờ | C6: 24–36 tháng | D6: Hiện diện tại thị trường đã chứng minh | E6: Lập VPĐD tại 1–2 hub (Quảng Châu & Rotterdam/Dubai); chăm khách lớn, QC tại chỗ; đăng ký nhãn hiệu & bảo hộ IP. | F6: VPĐD hỗ trợ nhà phân phối
A7: PH4 | B7: Nội địa hóa | C7: 36 tháng+ | D7: Nắm khách cuối & biên lợi nhuận | E7: Lập công ty con + kho lạnh ở thị trường ≥1 container/tuần; tự làm importer of record, bán thẳng retail/HORECA; JV ở thị trường rào cản cao. | F7: Công ty con / JV

Sheet RAW_Action
A1: RAW_Action — Việc cần làm 90 ngày
A2: PK = ActionID. Priority 1=làm trước. Sửa trực tiếp.
A3: ActionID | B3: Priority | C3: Title_VI | D3: Detail_VI | E3: TargetMarket_VI
A4: ACT1 | B4: 1 | C4: Khóa hồ sơ tuân thủ | D4: Rà soát & gia hạn GACC, BRC, HALAL, FSVP agent (Mỹ), C/O form VK (Hàn) — vé vào cửa từng thị trường. | E4: Tất cả
A5: ACT2 | B5: 2 | C5: Sàng lọc & chốt nhà phân phối | D5: Chọn 1 nhà phân phối độc quyền/vùng có giấy phép nhập khẩu & mạng lưới sẵn, ký KPI doanh số. | E5: Trung Quốc, Hàn Quốc
A6: ACT3 | B6: 3 | C6: Thiết lập hub kho lạnh EU | D6: Đặt tồn ký gửi tại Rotterdam làm bàn đạp phủ Hà Lan–Đức, rút ngắn thời gian giao & tăng tin cậy. | E6: Hà Lan, Đức

Sheet BRG_Market_Model
A1: BRG_Market_Model — Ma trận ưu tiên (Thị trường × Mô hình)
A2: FK: MarketID, ModelID. Score 3=cao/2=TB-sau/1=thấp/0=không áp dụng. Sequence ①②③ = thứ tự triển khai. KeyMM tự sinh, không sửa.
A3: MarketID | B3: ModelID | C3: Score | D3: ScoreLabel | E3: Sequence | F3: Note_VI | G3: KeyMM
A4: MK001 | B4: MOD1 | C4: 3 | D4: Cao | E4: ① | F4: XK chính ngạch — nền tảng | G4: MK001|MOD1
A5: MK001 | B5: MOD2 | C5: 2 | D5: TB | F5: Chỉ để xả hàng phụ | G5: MK001|MOD2
A6: MK001 | B6: MOD3 | C6: 3 | D6: Cao | E6: ② | F6: NPP độc quyền có guanxi | G6: MK001|MOD3
A7: MK001 | B7: MOD4 | C7: 2 | D7: Sau | E7: ③ | F7: VPĐD Quảng Châu khi ổn định | G7: MK001|MOD4
A8: MK001 | B8: MOD5 | C8: 2 | D8: Có ĐK | F8: Khi volume rất lớn | G8: MK001|MOD5
A9: MK001 | B9: MOD6 | C9: 2 | D9: Có ĐK | F9: JV vượt rào cản | G9: MK001|MOD6
A10: MK001 | B10: MOD7 | C10: 2 | D10: Tmall | F10: Tmall Global cho bán lẻ | G10: MK001|MOD7
A11: MK004 | B11: MOD1 | C11: 3 | D11: Cao | E11: ① | F11: Distributor + FSVP agent | G11: MK004|MOD1
A12: MK004 | B12: MOD2 | C12: 2 | D12: TB | F12: Broker ethnic | G12: MK004|MOD2
A13: MK004 | B13: MOD3 | C13: 2 | D13: TB | F13: NPP vùng | G13: MK004|MOD3
A14: MK004 | B14: MOD4 | C14: 1 | D14: Thấp | F14: Chưa cần VPĐD | G14: MK004|MOD4
A15: MK004 | B15: MOD5 | C15: 2 | D15: Sau | E15: ② | F15: Công ty con khi đủ volume | G15: MK004|MOD5
A16: MK004 | B16: MOD6 | C16: 1 | D16: Thấp | F16: Ít phù hợp | G16: MK004|MOD6
A17: MK004 | B17: MOD7 | C17: 2 | D17: Amazon | F17: Amazon cho chả giò | G17: MK004|MOD7
A18: MK002 | B18: MOD1 | C18: 3 | D18: Cao | E18: ① | F18: Importer Rotterdam | G18: MK002|MOD1
A19: MK002 | B19: MOD2 | C19: 1 | D19: Thấp | F19: Không cần trung gian | G19: MK002|MOD2
A20: MK002 | B20: MOD3 | C20: 2 | D20: TB | F20: NPP nếu cần phủ retail | G20: MK002|MOD3
A21: MK002 | B21: MOD4 | C21: 2 | D21: Hub | E21: ② | F21: VPĐD làm hub EU | G21: MK002|MOD4
A22: MK002 | B22: MOD5 | C22: 1 | D22: Thấp | F22: Chưa cần pháp nhân | G22: MK002|MOD5
A23: MK002 | B23: MOD6 | C23: 0 | D23: – | F23: Không áp dụng | G23: MK002|MOD6
A24: MK002 | B24: MOD7 | C24: 3 | D24: Hub EU | E24: ① | F24: Kho ký gửi hub EU | G24: MK002|MOD7
A25: MK003 | B25: MOD1 | C25: 3 | D25: Cao | E25: ① | F25: Importer/foodservice | G25: MK003|MOD1
A26: MK003 | B26: MOD2 | C26: 1 | D26: Thấp | F26: Không cần | G26: MK003|MOD2
A27: MK003 | B27: MOD3 | C27: 2 | D27: TB | F27: NPP retail | G27: MK003|MOD3
A28: MK003 | B28: MOD4 | C28: 1 | D28: Thấp | F28: Phủ qua hub NL | G28: MK003|MOD4
A29: MK003 | B29: MOD5 | C29: 0 | D29: – | F29: Không áp dụng | G29: MK003|MOD5
A30: MK003 | B30: MOD6 | C30: 0 | D30: – | F30: Không áp dụng | G30: MK003|MOD6
A31: MK003 | B31: MOD7 | C31: 2 | D31: Qua NL | F31: Qua hub Hà Lan | G31: MK003|MOD7
A32: MK005 | B32: MOD1 | C32: 2 | D32: TB | F32: Importer trực tiếp | G32: MK005|MOD1
A33: MK005 | B33: MOD2 | C33: 1 | D33: Thấp | F33: Ít dùng | G33: MK005|MOD2
A34: MK005 | B34: MOD3 | C34: 3 | D34: Cao | E34: ① | F34: NPP bản địa nắm giấy phép | G34: MK005|MOD3
A35: MK005 | B35: MOD4 | C35: 1 | D35: Thấp | F35: Chưa cần | G35: MK005|MOD4
A36: MK005 | B36: MOD5 | C36: 1 | D36: Thấp | F36: Rào cản cao | G36: MK005|MOD5
A37: MK005 | B37: MOD6 | C37: 2 | D37: Nếu mở rộng | F37: JV khi scale | G37: MK005|MOD6
A38: MK005 | B38: MOD7 | C38: 1 | D38: Thấp | F38: Ít phù hợp | G38: MK005|MOD7
A39: MK006 | B39: MOD1 | C39: 3 | D39: Cao | E39: ① | F39: Importer Dubai HALAL | G39: MK006|MOD1
A40: MK006 | B40: MOD2 | C40: 2 | D40: TB | F40: Broker khu vực | G40: MK006|MOD2
...

Sheet V_PriorityMatrix
A1: V_PriorityMatrix — MASTER (tự tổng hợp từ BRG_Market_Model)
A2: Mỗi ô = nhãn điểm + thứ tự triển khai (①②③). KHÔNG sửa tay — chỉnh ở BRG/RAW.
A4: Thị trường \ Mô hình | B4: XK trực tiếp | C4: XK gián tiếp | D4: NPP độc quyền | E4: VPĐD | F4: Công ty con+kho | G4: Liên doanh | H4: Kho NQ/TMĐT | I4: Ưu tiên tổng
A5: =INDEX('RAW_Market'!$B:$B,MATCH($K5,'RAW_Market'!$A:$A,0))&" ("&TEXT(INDEX('RAW_Market'!$E:$E,MATCH($K5,'RAW_Market'!$A:$A,0)),"0%")&")" -> Trung Quốc (45%) | B5: =IFERROR(TRIM(INDEX(BRG_Market_Model!$D:$D,MATCH($K5&"|"&B$13,BRG_Market_Model!$G:$G,0))&" "&INDEX(BRG_Market_Model!$E:$E,MATCH($K5&"|"&B$13,BRG_Market_Model!$G:$G,0))),"") -> Cao ① | C5: =IFERROR(TRIM(INDEX(BRG_Market_Model!$D:$D,MATCH($K5&"|"&C$13,BRG_Market_Model!$G:$G,0))&" "&INDEX(BRG_Market_Model!$E:$E,MATCH($K5&"|"&C$13,BRG_Market_Model!$G:$G,0))),"") -> TB | D5: =IFERROR(TRIM(INDEX(BRG_Market_Model!$D:$D,MATCH($K5&"|"&D$13,BRG_Market_Model!$G:$G,0))&" "&INDEX(BRG_Market_Model!$E:$E,MATCH($K5&"|"&D$13,BRG_Market_Model!$G:$G,0))),"") -> Cao ② | E5: =IFERROR(TRIM(INDEX(BRG_Market_Model!$D:$D,MATCH($K5&"|"&E$13,BRG_Market_Model!$G:$G,0))&" "&INDEX(BRG_Market_Model!$E:$E,MATCH($K5&"|"&E$13,BRG_Market_Model!$G:$G,0))),"") -> Sau ③ | F5: =IFERROR(TRIM(INDEX(BRG_Market_Model!$D:$D,MATCH($K5&"|"&F$13,BRG_Market_Model!$G:$G,0))&" "&INDEX(BRG_Market_Model!$E:$E,MATCH($K5&"|"&F$13,BRG_Market_Model!$G:$G,0))),"") -> Có ĐK | G5: =IFERROR(TRIM(INDEX(BRG_Market_Model!$D:$D,MATCH($K5&"|"&G$13,BRG_Market_Model!$G:$G,0))&" "&INDEX(BRG_Market_Model!$E:$E,MATCH($K5&"|"&G$13,BRG_Market_Model!$G:$G,0))),"") -> Có ĐK | H5: =IFERROR(TRIM(INDEX(BRG_Market_Model!$D:$D,MATCH($K5&"|"&H$13,BRG_Market_Model!$G:$G,0))&" "&INDEX(BRG_Market_Model!$E:$E,MATCH($K5&"|"&H$13,BRG_Market_Model!$G:$G,0))),"") -> Tmall | I5: =INDEX('RAW_Market'!$G:$G,MATCH($K5,'RAW_Market'!$A:$A,0)) -> 1 | K5: MK001
A6: =INDEX('RAW_Market'!$B:$B,MATCH($K6,'RAW_Market'!$A:$A,0))&" ("&TEXT(INDEX('RAW_Market'!$E:$E,MATCH($K6,'RAW_Market'!$A:$A,0)),"0%")&")" -> Mỹ (15%) | B6: =IFERROR(TRIM(INDEX(BRG_Market_Model!$D:$D,MATCH($K6&"|"&B$13,BRG_Market_Model!$G:$G,0))&" "&INDEX(BRG_Market_Model!$E:$E,MATCH($K6&"|"&B$13,BRG_Market_Model!$G:$G,0))),"") -> Cao ① | C6: =IFERROR(TRIM(INDEX(BRG_Market_Model!$D:$D,MATCH($K6&"|"&C$13,BRG_Market_Model!$G:$G,0))&" "&INDEX(BRG_Market_Model!$E:$E,MATCH($K6&"|"&C$13,BRG_Market_Model!$G:$G,0))),"") -> TB | D6: =IFERROR(TRIM(INDEX(BRG_Market_Model!$D:$D,MATCH($K6&"|"&D$13,BRG_Market_Model!$G:$G,0))&" "&INDEX(BRG_Market_Model!$E:$E,MATCH($K6&"|"&D$13,BRG_Market_Model!$G:$G,0))),"") -> TB | E6: =IFERROR(TRIM(INDEX(BRG_Market_Model!$D:$D,MATCH($K6&"|"&E$13,BRG_Market_Model!$G:$G,0))&" "&INDEX(BRG_Market_Model!$E:$E,MATCH($K6&"|"&E$13,BRG_Market_Model!$G:$G,0))),"") -> Thấp | F6: =IFERROR(TRIM(INDEX(BRG_Market_Model!$D:$D,MATCH($K6&"|"&F$13,BRG_Market_Model!$G:$G,0))&" "&INDEX(BRG_Market_Model!$E:$E,MATCH($K6&"|"&F$13,BRG_Market_Model!$G:$G,0))),"") -> Sau ② | G6: =IFERROR(TRIM(INDEX(BRG_Market_Model!$D:$D,MATCH($K6&"|"&G$13,BRG_Market_Model!$G:$G,0))&" "&INDEX(BRG_Market_Model!$E:$E,MATCH($K6&"|"&G$13,BRG_Market_Model!$G:$G,0))),"") -> Thấp | H6: =IFERROR(TRIM(INDEX(BRG_Market_Model!$D:$D,MATCH($K6&"|"&H$13,BRG_Market_Model!$G:$G,0))&" "&INDEX(BRG_Market_Model!$E:$E,MATCH($K6&"|"&H$13,BRG_Market_Model!$G:$G,0))),"") -> Amazon | I6: =INDEX('RAW_Market'!$G:$G,MATCH($K6,'RAW_Market'!$A:$A,0)) -> 2 | K6: MK004
A7: =INDEX('RAW_Market'!$B:$B,MATCH($K7,'RAW_Market'!$A:$A,0))&" ("&TEXT(INDEX('RAW_Market'!$E:$E,MATCH($K7,'RAW_Market'!$A:$A,0)),"0%")&")" -> Hà Lan (EU) (15%) | B7: =IFERROR(TRIM(INDEX(BRG_Market_Model!$D:$D,MATCH($K7&"|"&B$13,BRG_Market_Model!$G:$G,0))&" "&INDEX(BRG_Market_Model!$E:$E,MATCH($K7&"|"&B$13,BRG_Market_Model!$G:$G,0))),"") -> Cao ① | C7: =IFERROR(TRIM(INDEX(BRG_Market_Model!$D:$D,MATCH($K7&"|"&C$13,BRG_Market_Model!$G:$G,0))&" "&INDEX(BRG_Market_Model!$E:$E,MATCH($K7&"|"&C$13,BRG_Market_Model!$G:$G,0))),"") -> Thấp | D7: =IFERROR(TRIM(INDEX(BRG_Market_Model!$D:$D,MATCH($K7&"|"&D$13,BRG_Market_Model!$G:$G,0))&" "&INDEX(BRG_Market_Model!$E:$E,MATCH($K7&"|"&D$13,BRG_Market_Model!$G:$G,0))),"") -> TB | E7: =IFERROR(TRIM(INDEX(BRG_Market_Model!$D:$D,MATCH($K7&"|"&E$13,BRG_Market_Model!$G:$G,0))&" "&INDEX(BRG_Market_Model!$E:$E,MATCH($K7&"|"&E$13,BRG_Market_Model!$G:$G,0))),"") -> Hub ② | F7: =IFERROR(TRIM(INDEX(BRG_Market_Model!$D:$D,MATCH($K7&"|"&F$13,BRG_Market_Model!$G:$G,0))&" "&INDEX(BRG_Market_Model!$E:$E,MATCH($K7&"|"&F$13,BRG_Market_Model!$G:$G,0))),"") -> Thấp | G7: =IFERROR(TRIM(INDEX(BRG_Market_Model!$D:$D,MATCH($K7&"|"&G$13,BRG_Market_Model!$G:$G,0))&" "&INDEX(BRG_Market_Model!$E:$E,MATCH($K7&"|"&G$13,BRG_Market_Model!$G:$G,0))),"") -> – | H7: =IFERROR(TRIM(INDEX(BRG_Market_Model!$D:$D,MATCH($K7&"|"&H$13,BRG_Market_Model!$G:$G,0))&" "&INDEX(BRG_Market_Model!$E:$E,MATCH($K7&"|"&H$13,BRG_Market_Model!$G:$G,0))),"") -> Hub EU ① | I7: =INDEX('RAW_Market'!$G:$G,MATCH($K7,'RAW_Market'!$A:$A,0)) -> 3 | K7: MK002
A8: =INDEX('RAW_Market'!$B:$B,MATCH($K8,'RAW_Market'!$A:$A,0))&" ("&TEXT(INDEX('RAW_Market'!$E:$E,MATCH($K8,'RAW_Market'!$A:$A,0)),"0%")&")" -> Đức (EU) (10%) | B8: =IFERROR(TRIM(INDEX(BRG_Market_Model!$D:$D,MATCH($K8&"|"&B$13,BRG_Market_Model!$G:$G,0))&" "&INDEX(BRG_Market_Model!$E:$E,MATCH($K8&"|"&B$13,BRG_Market_Model!$G:$G,0))),"") -> Cao ① | C8: =IFERROR(TRIM(INDEX(BRG_Market_Model!$D:$D,MATCH($K8&"|"&C$13,BRG_Market_Model!$G:$G,0))&" "&INDEX(BRG_Market_Model!$E:$E,MATCH($K8&"|"&C$13,BRG_Market_Model!$G:$G,0))),"") -> Thấp | D8: =IFERROR(TRIM(INDEX(BRG_Market_Model!$D:$D,MATCH($K8&"|"&D$13,BRG_Market_Model!$G:$G,0))&" "&INDEX(BRG_Market_Model!$E:$E,MATCH($K8&"|"&D$13,BRG_Market_Model!$G:$G,0))),"") -> TB | E8: =IFERROR(TRIM(INDEX(BRG_Market_Model!$D:$D,MATCH($K8&"|"&E$13,BRG_Market_Model!$G:$G,0))&" "&INDEX(BRG_Market_Model!$E:$E,MATCH($K8&"|"&E$13,BRG_Market_Model!$G:$G,0))),"") -> Thấp | F8: =IFERROR(TRIM(INDEX(BRG_Market_Model!$D:$D,MATCH($K8&"|"&F$13,BRG_Market_Model!$G:$G,0))&" "&INDEX(BRG_Market_Model!$E:$E,MATCH($K8&"|"&F$13,BRG_Market_Model!$G:$G,0))),"") -> – | G8: =IFERROR(TRIM(INDEX(BRG_Market_Model!$D:$D,MATCH($K8&"|"&G$13,BRG_Market_Model!$G:$G,0))&" "&INDEX(BRG_Market_Model!$E:$E,MATCH($K8&"|"&G$13,BRG_Market_Model!$G:$G,0))),"") -> – | H8: =IFERROR(TRIM(INDEX(BRG_Market_Model!$D:$D,MATCH($K8&"|"&H$13,BRG_Market_Model!$G:$G,0))&" "&INDEX(BRG_Market_Model!$E:$E,MATCH($K8&"|"&H$13,BRG_Market_Model!$G:$G,0))),"") -> Qua NL | I8: =INDEX('RAW_Market'!$G:$G,MATCH($K8,'RAW_Market'!$A:$A,0)) -> 4 | K8: MK003
A9: =INDEX('RAW_Market'!$B:$B,MATCH($K9,'RAW_Market'!$A:$A,0))&" ("&TEXT(INDEX('RAW_Market'!$E:$E,MATCH($K9,'RAW_Market'!$A:$A,0)),"0%")&")" -> Hàn Quốc (10%) | B9: =IFERROR(TRIM(INDEX(BRG_Market_Model!$D:$D,MATCH($K9&"|"&B$13,BRG_Market_Model!$G:$G,0))&" "&INDEX(BRG_Market_Model!$E:$E,MATCH($K9&"|"&B$13,BRG_Market_Model!$G:$G,0))),"") -> TB | C9: =IFERROR(TRIM(INDEX(BRG_Market_Model!$D:$D,MATCH($K9&"|"&C$13,BRG_Market_Model!$G:$G,0))&" "&INDEX(BRG_Market_Model!$E:$E,MATCH($K9&"|"&C$13,BRG_Market_Model!$G:$G,0))),"") -> Thấp | D9: =IFERROR(TRIM(INDEX(BRG_Market_Model!$D:$D,MATCH($K9&"|"&D$13,BRG_Market_Model!$G:$G,0))&" "&INDEX(BRG_Market_Model!$E:$E,MATCH($K9&"|"&D$13,BRG_Market_Model!$G:$G,0))),"") -> Cao ① | E9: =IFERROR(TRIM(INDEX(BRG_Market_Model!$D:$D,MATCH($K9&"|"&E$13,BRG_Market_Model!$G:$G,0))&" "&INDEX(BRG_Market_Model!$E:$E,MATCH($K9&"|"&E$13,BRG_Market_Model!$G:$G,0))),"") -> Thấp | F9: =IFERROR(TRIM(INDEX(BRG_Market_Model!$D:$D,MATCH($K9&"|"&F$13,BRG_Market_Model!$G:$G,0))&" "&INDEX(BRG_Market_Model!$E:$E,MATCH($K9&"|"&F$13,BRG_Market_Model!$G:$G,0))),"") -> Thấp | G9: =IFERROR(TRIM(INDEX(BRG_Market_Model!$D:$D,MATCH($K9&"|"&G$13,BRG_Market_Model!$G:$G,0))&" "&INDEX(BRG_Market_Model!$E:$E,MATCH($K9&"|"&G$13,BRG_Market_Model!$G:$G,0))),"") -> Nếu mở rộng | H9: =IFERROR(TRIM(INDEX(BRG_Market_Model!$D:$D,MATCH($K9&"|"&H$13,BRG_Market_Model!$G:$G,0))&" "&INDEX(BRG_Market_Model!$E:$E,MATCH($K9&"|"&H$13,BRG_Market_Model!$G:$G,0))),"") -> Thấp | I9: =INDEX('RAW_Market'!$G:$G,MATCH($K9,'RAW_Market'!$A:$A,0)) -> 5 | K9: MK005
A10: =INDEX('RAW_Market'!$B:$B,MATCH($K10,'RAW_Market'!$A:$A,0))&" ("&TEXT(INDEX('RAW_Market'!$E:$E,MATCH($K10,'RAW_Market'!$A:$A,0)),"0%")&")" -> UAE (Trung Đông) (5%) | B10: =IFERROR(TRIM(INDEX(BRG_Market_Model!$D:$D,MATCH($K10&"|"&B$13,BRG_Market_Model!$G:$G,0))&" "&INDEX(BRG_Market_Model!$E:$E,MATCH($K10&"|"&B$13,BRG_Market_Model!$G:$G,0))),"") -> Cao ① | C10: =IFERROR(TRIM(INDEX(BRG_Market_Model!$D:$D,MATCH($K10&"|"&C$13,BRG_Market_Model!$G:$G,0))&" "&INDEX(BRG_Market_Model!$E:$E,MATCH($K10&"|"&C$13,BRG_Market_Model!$G:$G,0))),"") -> TB | D10: =IFERROR(TRIM(INDEX(BRG_Market_Model!$D:$D,MATCH($K10&"|"&D$13,BRG_Market_Model!$G:$G,0))&" "&INDEX(BRG_Market_Model!$E:$E,MATCH($K10&"|"&D$13,BRG_Market_Model!$G:$G,0))),"") -> TB | E10: =IFERROR(TRIM(INDEX(BRG_Market_Model!$D:$D,MATCH($K10&"|"&E$13,BRG_Market_Model!$G:$G,0))&" "&INDEX(BRG_Market_Model!$E:$E,MATCH($K10&"|"&E$13,BRG_Market_Model!$G:$G,0))),"") -> Hub ② | F10: =IFERROR(TRIM(INDEX(BRG_Market_Model!$D:$D,MATCH($K10&"|"&F$13,BRG_Market_Model!$G:$G,0))&" "&INDEX(BRG_Market_Model!$E:$E,MATCH($K10&"|"&F$13,BRG_Market_Model!$G:$G,0))),"") -> Thấp | G10: =IFERROR(TRIM(INDEX(BRG_Market_Model!$D:$D,MATCH($K10&"|"&G$13,BRG_Market_Model!$G:$G,0))&" "&INDEX(BRG_Market_Model!$E:$E,MATCH($K10&"|"&G$13,BRG_Market_Model!$G:$G,0))),"") -> – | H10: =IFERROR(TRIM(INDEX(BRG_Market_Model!$D:$D,MATCH($K10&"|"&H$13,BRG_Market_Model!$G:$G,0))&" "&INDEX(BRG_Market_Model!$E:$E,MATCH($K10&"|"&H$13,BRG_Market_Model!$G:$G,0))),"") -> HORECA | I10: =INDEX('RAW_Market'!$G:$G,MATCH($K10,'RAW_Market'!$A:$A,0)) -> 6 | K10: MK006
A12: (vùng phụ trợ — không xóa)
B13: MOD1 | C13: MOD2 | D13: MOD3 | E13: MOD4 | F13: MOD5 | G13: MOD6 | H13: MOD7
A15: Chú giải:
A16: 3=Ưu tiên cao/làm ngay
A17: 2=Giai đoạn sau/có điều kiện
A18: 1=Ít phù hợp
A19: 0 / – =Không áp dụng

Sheet V_MarketStrategy
A1: V_MarketStrategy — MASTER (tự tổng hợp từ RAW_Market + RAW_BuyerCulture)
A2: KHÔNG sửa tay — chỉnh dữ liệu ở RAW_Market / RAW_BuyerCulture.
A4: Hạng | B4: Thị trường | C4: Quốc gia | D4: Thị phần | E4: Mô hình đề xuất | F4: Phong cách quyết định | G4: Giá trị buyer coi trọng
A5: =INDEX('RAW_Market'!$G:$G,MATCH($L5,'RAW_Market'!$A:$A,0)) -> 1 | B5: =INDEX('RAW_Market'!$B:$B,MATCH($L5,'RAW_Market'!$A:$A,0)) -> Trung Quốc | C5: =INDEX('RAW_Market'!$C:$C,MATCH($L5,'RAW_Market'!$A:$A,0)) -> China | D5: =INDEX('RAW_Market'!$E:$E,MATCH($L5,'RAW_Market'!$A:$A,0)) -> 0.45 | E5: =INDEX('RAW_Market'!$H:$H,MATCH($L5,'RAW_Market'!$A:$A,0)) -> XK chính ngạch → NPP độc quyền → VPĐD Quảng Châu | F5: =INDEX(RAW_BuyerCulture!$C:$C,MATCH($L5,RAW_BuyerCulture!$A:$A,0)) -> Dựa quan hệ (关系 guanxi) & tin cậy cá nhân; gặp mặt, ăn uống trước khi chốt. | G5: =INDEX(RAW_BuyerCulture!$E:$E,MATCH($L5,RAW_BuyerCulture!$A:$A,0)) -> Tốc độ giao & ổn định nguồn; giá cạnh tranh. | L5: MK001
A6: =INDEX('RAW_Market'!$G:$G,MATCH($L6,'RAW_Market'!$A:$A,0)) -> 2 | B6: =INDEX('RAW_Market'!$B:$B,MATCH($L6,'RAW_Market'!$A:$A,0)) -> Mỹ | C6: =INDEX('RAW_Market'!$C:$C,MATCH($L6,'RAW_Market'!$A:$A,0)) -> USA | D6: =INDEX('RAW_Market'!$E:$E,MATCH($L6,'RAW_Market'!$A:$A,0)) -> 0.15 | E6: =INDEX('RAW_Market'!$H:$H,MATCH($L6,'RAW_Market'!$A:$A,0)) -> XK trực tiếp cho distributor + FSVP agent → Công ty con + kho lạnh khi đủ volume | F6: =INDEX(RAW_BuyerCulture!$C:$C,MATCH($L6,RAW_BuyerCulture!$A:$A,0)) -> Thực dụng, dựa hiệu suất & hợp đồng chặt; quyết nhanh. | G6: =INDEX(RAW_BuyerCulture!$E:$E,MATCH($L6,RAW_BuyerCulture!$A:$A,0)) -> Giá cạnh tranh, nguồn cung lớn ổn định, trách nhiệm pháp lý & bảo hiểm. | L6: MK004
A7: =INDEX('RAW_Market'!$G:$G,MATCH($L7,'RAW_Market'!$A:$A,0)) -> 3 | B7: =INDEX('RAW_Market'!$B:$B,MATCH($L7,'RAW_Market'!$A:$A,0)) -> Hà Lan (EU) | C7: =INDEX('RAW_Market'!$C:$C,MATCH($L7,'RAW_Market'!$A:$A,0)) -> Netherlands | D7: =INDEX('RAW_Market'!$E:$E,MATCH($L7,'RAW_Market'!$A:$A,0)) -> 0.15 | E7: =INDEX('RAW_Market'!$H:$H,MATCH($L7,'RAW_Market'!$A:$A,0)) -> XK trực tiếp cho importer Rotterdam → Kho lạnh ký gửi làm hub EU | F7: =INDEX(RAW_BuyerCulture!$C:$C,MATCH($L7,RAW_BuyerCulture!$A:$A,0)) -> Thẳng thắn, dựa số liệu, quyết nhanh khi đủ dữ kiện. | G7: =INDEX(RAW_BuyerCulture!$E:$E,MATCH($L7,RAW_BuyerCulture!$A:$A,0)) -> Bền vững & chứng nhận (ASC, MSC, GlobalG.A.P), truy xuất minh bạch. | L7: MK002
A8: =INDEX('RAW_Market'!$G:$G,MATCH($L8,'RAW_Market'!$A:$A,0)) -> 4 | B8: =INDEX('RAW_Market'!$B:$B,MATCH($L8,'RAW_Market'!$A:$A,0)) -> Đức (EU) | C8: =INDEX('RAW_Market'!$C:$C,MATCH($L8,'RAW_Market'!$A:$A,0)) -> Germany | D8: =INDEX('RAW_Market'!$E:$E,MATCH($L8,'RAW_Market'!$A:$A,0)) -> 0.10 | E8: =INDEX('RAW_Market'!$H:$H,MATCH($L8,'RAW_Market'!$A:$A,0)) -> XK trực tiếp cho importer/foodservice qua hub Hà Lan; không cần pháp nhân riêng | F8: =INDEX(RAW_BuyerCulture!$C:$C,MATCH($L8,RAW_BuyerCulture!$A:$A,0)) -> Kỹ tính, chuộng quy trình & giấy tờ; kiểm tra kỹ trước cam kết dài hạn. | G8: =INDEX(RAW_BuyerCulture!$E:$E,MATCH($L8,RAW_BuyerCulture!$A:$A,0)) -> Chất lượng ổn định tuyệt đối; BRC/IFS, organic; trách nhiệm chuỗi cung ứng. | L8: MK003
A9: =INDEX('RAW_Market'!$G:$G,MATCH($L9,'RAW_Market'!$A:$A,0)) -> 5 | B9: =INDEX('RAW_Market'!$B:$B,MATCH($L9,'RAW_Market'!$A:$A,0)) -> Hàn Quốc | C9: =INDEX('RAW_Market'!$C:$C,MATCH($L9,'RAW_Market'!$A:$A,0)) -> South Korea | D9: =INDEX('RAW_Market'!$E:$E,MATCH($L9,'RAW_Market'!$A:$A,0)) -> 0.10 | E9: =INDEX('RAW_Market'!$H:$H,MATCH($L9,'RAW_Market'!$A:$A,0)) -> Nhà phân phối/importer bản địa (họ nắm giấy phép) → cân nhắc JV nếu mở rộng | F9: =INDEX(RAW_BuyerCulture!$C:$C,MATCH($L9,RAW_BuyerCulture!$A:$A,0)) -> Tôn ti, quyết định tập thể; cần nhiều vòng gặp & kiên nhẫn. | G9: =INDEX(RAW_BuyerCulture!$E:$E,MATCH($L9,RAW_BuyerCulture!$A:$A,0)) -> Chất lượng & đóng gói cực cao; ngoại hình sản phẩm; test mẫu kỹ. | L9: MK005
A10: =INDEX('RAW_Market'!$G:$G,MATCH($L10,'RAW_Market'!$A:$A,0)) -> 6 | B10: =INDEX('RAW_Market'!$B:$B,MATCH($L10,'RAW_Market'!$A:$A,0)) -> UAE (Trung Đông) | C10: =INDEX('RAW_Market'!$C:$C,MATCH($L10,'RAW_Market'!$A:$A,0)) -> UAE | D10: =INDEX('RAW_Market'!$E:$E,MATCH($L10,'RAW_Market'!$A:$A,0)) -> 0.05 | E10: =INDEX('RAW_Market'!$H:$H,MATCH($L10,'RAW_Market'!$A:$A,0)) -> XK trực tiếp cho importer Dubai (HALAL) → VPĐD/free-zone làm hub tái xuất GCC & châu Phi | F10: =INDEX(RAW_BuyerCulture!$C:$C,MATCH($L10,RAW_BuyerCulture!$A:$A,0)) -> Dựa quan hệ & uy tín cá nhân; đàm phán linh hoạt, không gấp gáp. | G10: =INDEX(RAW_BuyerCulture!$E:$E,MATCH($L10,RAW_BuyerCulture!$A:$A,0)) -> Đối tác dài hạn, đáng tin; sản phẩm HALAL đúng chuẩn. | L10: MK006
